<?xml version="1.0" encoding="utf-8"?>
<!-- This URDF was automatically created by SolidWorks to URDF Exporter! Originally created by Stephen Brawner (brawner@gmail.com) 
     Commit Version: 1.6.0-1-g15f4949  Build Version: 1.6.7594.29634
     For more information, please see http://wiki.ros.org/sw_urdf_exporter -->
<robot
  name="6dof">
  <!-- base -->
  <link
    name="base">
    <inertial>
      <origin
        xyz="-0.000347374556861547 0.000101207333103441 0.0782524999724827"
        rpy="0 0 0" />
      <mass
        value="2.98839561693632" />
      <inertia
        ixx="0.00853888049906063"
        ixy="1.32639418659869E-06"
        ixz="-5.10062501073997E-05"
        iyy="0.0148391707873313"
        iyz="-7.38801973712153E-06"
        izz="0.0112310816428658" />
    </inertial>
    <visual>
      <origin
        xyz="0 0 0"
        rpy="0 0 0" />
      <geometry>
        <mesh
          filename="/meshes_origin/base.STL" />
      </geometry>
      <material
        name="">
        <color
          rgba="0.898039215686275 0.917647058823529 0.929411764705882 1" />
      </material>
    </visual>
    <collision>
      <origin
        xyz="0 0 0"
        rpy="0 0 0" />
      <geometry>
        <mesh
          filename="/meshes_origin/base.obj" />
      </geometry>
    </collision>
  </link>
  <!-- link1 -->
  <link
    name="link1">
    <inertial>
      <origin
        xyz="-0.00172366771693358 -2.55178151346815E-05 0.133968888509977"
        rpy="0 0 0" />
      <mass
        value="3.30743881556333" />
      <inertia
        ixx="0.0137983780124978"
        ixy="5.47986713037484E-06"
        ixz="0.000178679862765163"
        iyy="0.0153291542700041"
        iyz="-1.59398381387562E-06"
        izz="0.00899596989685085" />
    </inertial>
    <visual>
      <origin
        xyz="0 0 0"
        rpy="0 0 0" />
      <geometry>
        <mesh
          filename="/meshes_origin/link1.STL" />
      </geometry>
      <material
        name="">
        <color
          rgba="0.898039215686275 0.917647058823529 0.929411764705882 1" />
      </material>
    </visual>
    <collision>
      <origin
        xyz="0 0 0"
        rpy="0 0 0" />
      <geometry>
        <mesh
          filename="/meshes_origin/link1.obj" />
      </geometry>
    </collision>
  </link>
  <!-- joint1 -->
  <joint
    name="joint1"
    type="continuous">
    <origin
      xyz="0 -0.136 0"
      rpy="1.5708 0 0" />
    <parent
      link="base" />
    <child
      link="link1" />
    <axis
      xyz="0 0 1" />
    <limit
      lower="0"
      upper="0"
      effort="0"
      velocity="0" />
  </joint>
  <!-- link2 -->
  <link
    name="link2">
    <inertial>
      <origin
        xyz="0.0062635082635212 0.0195692461832506 0.281532730459941"
        rpy="0 0 0" />
      <mass
        value="3.97302477404015" />
      <inertia
        ixx="0.139145612346073"
        ixy="0.000105721459127739"
        ixz="-0.000331195352477424"
        iyy="0.140863892395562"
        iyz="0.0077917679287208"
        izz="0.0129377782724841" />
    </inertial>
    <visual>
      <origin
        xyz="0 0 0"
        rpy="0 0 0" />
      <geometry>
        <mesh
          filename="/meshes_origin/link2.STL" />
      </geometry>
      <material
        name="">
        <color
          rgba="0.898039215686275 0.917647058823529 0.929411764705882 1" />
      </material>
    </visual>
    <collision>
      <origin
        xyz="0 0 0"
        rpy="0 0 0" />
      <geometry>
        <mesh
          filename="/meshes_origin/link2.obj" />
      </geometry>
    </collision>
  </link>
  <!-- joint2 -->
  <joint
    name="joint2"
    type="continuous">
    <origin
      xyz="0 0 0.149"
      rpy="0 0 0" />
    <parent
      link="link1" />
    <child
      link="link2" />
    <axis
      xyz="1 0 0" />
  </joint>
  <!-- link3 -->
  <link
    name="link3">
    <inertial>
      <origin
        xyz="0.00188192600890507 0.0120711602231872 0.145343319561833"
        rpy="0 0 0" />
      <mass
        value="1.97462395109401" />
      <inertia
        ixx="0.0169282371667443"
        ixy="-2.94751165263631E-05"
        ixz="0.000499612683049639"
        iyy="0.0176543239756729"
        iyz="0.00116547471427261"
        izz="0.00528556688777832" />
    </inertial>
    <visual>
      <origin
        xyz="0 0 0"
        rpy="0 0 0" />
      <geometry>
        <mesh
          filename="/meshes_origin/link3.STL" />
      </geometry>
      <material
        name="">
        <color
          rgba="0.898039215686275 0.917647058823529 0.929411764705882 1" />
      </material>
    </visual>
    <collision>
      <origin
        xyz="0 0 0"
        rpy="0 0 0" />
      <geometry>
        <mesh
          filename="/meshes_origin/link3.obj" />
      </geometry>
    </collision>
  </link>
  <!-- joint3 -->
  <joint
    name="joint3"
    type="continuous">
    <origin
      xyz="0 0 0.45"
      rpy="0 0 -0.0077716" />
    <parent
      link="link2" />
    <child
      link="link3" />
    <axis
      xyz="0.99997 0.0077715 0" />
  </joint>
  <!-- link4 -->
  <link
    name="link4">
    <inertial>
      <origin
        xyz="0.00020365247201736 -7.72072988004458E-05 0.164805502894595"
        rpy="0 0 0" />
      <mass
        value="1.70517883594437" />
      <inertia
        ixx="0.00942998870494057"
        ixy="-5.3812866355169E-07"
        ixz="-1.74322059693261E-05"
        iyy="0.00973848659429674"
        iyz="4.96088010081163E-06"
        izz="0.00192244294499836" />
    </inertial>
    <visual>
      <origin
        xyz="0 0 0"
        rpy="0 0 0" />
      <geometry>
        <mesh
          filename="/meshes/link4.STL" />
      </geometry>
      <material
        name="">
        <color
          rgba="0.898039215686275 0.917647058823529 0.929411764705882 1" />
      </material>
    </visual>
    <collision>
      <origin
        xyz="0 0 0"
        rpy="0 0 0" />
      <geometry>
        <mesh
          filename="\meshes/link4.obj" />
      </geometry>
    </collision>
  </link>
  <!-- joint4 -->
  <joint
    name="joint4"
    type="continuous">
    <origin
      xyz="0 0 0.244"
      rpy="0 0 0.0077716" />
    <parent
      link="link3" />
    <child
      link="link4" />
    <axis
      xyz="0 0 1" />
  </joint>
  <!-- link5 -->
  <link
    name="link5">
    <inertial>
      <origin
        xyz="6.00095184746343E-05 -9.74145577642233E-05 0.138605284339217"
        rpy="0 0 0" />
      <mass
        value="1.39733499788996" />
      <inertia
        ixx="0.00512317439181702"
        ixy="1.01386145709815E-07"
        ixz="-0.000164045107246316"
        iyy="0.00601676055718181"
        iyz="4.15082833854892E-06"
        izz="0.00239968116036573" />
    </inertial>
    <visual>
      <origin
        xyz="0 0 0"
        rpy="0 0 0" />
      <geometry>
        <mesh
          filename="/meshes/link5.STL" />
      </geometry>
      <material
        name="">
        <color
          rgba="0.898039215686275 0.917647058823529 0.929411764705882 1" />
      </material>
    </visual>
    <collision>
      <origin
        xyz="0 0 0"
        rpy="0 0 0" />
      <geometry>
        <mesh
          filename="/meshes/link5.obj" />
      </geometry>
    </collision>
  </link>
  <!-- joint5 -->
  <joint
    name="joint5"
    type="continuous">
    <origin
      xyz="0 0 0.206"
      rpy="0 0 0" />
    <parent
      link="link4" />
    <child
      link="link5" />
    <axis
      xyz="1 0 0" />
  </joint>
  <!-- link6 -->
  <link
    name="link6">
    <inertial>
      <origin
        xyz="1.72877768598726E-07 -1.44805382755415E-08 0.0269186601342679"
        rpy="0 0 0" />
      <mass
        value="0.182564965845164" />
      <inertia
        ixx="8.94239749400423E-05"
        ixy="2.68081973662311E-10"
        ixz="-2.64892624422302E-09"
        iyy="0.000235016696094663"
        iyz="4.71060052104843E-11"
        izz="0.000181546254189962" />
    </inertial>
    <visual>
      <origin
        xyz="0 0 0"
        rpy="0 0 0" />
      <geometry>
        <mesh
          filename="/meshes/link6.STL" />
      </geometry>
      <material
        name="">
        <color
          rgba="0.898039215686275 0.917647058823529 0.929411764705882 1" />
      </material>
    </visual>
    <collision>
      <origin
        xyz="0 0 0"
        rpy="0 0 0" />
      <geometry>
        <mesh
          filename="/meshes/link6.obj" />
      </geometry>
    </collision>
  </link>
  <!-- joint6 -->
  <joint
    name="joint6"
    type="continuous">
    <origin
      xyz="0 0 0.199"
      rpy="0 0 0" />
    <parent
      link="link5" />
    <child
      link="link6" />
    <axis
      xyz="0 0 1" />
  </joint>
</robot>