<?xml version="1.0" encoding="utf-8"?>
<!-- This URDF was automatically created by SolidWorks to URDF Exporter! Originally created by Stephen Brawner (brawner@gmail.com) 
     Commit Version: 1.5.1-0-g916b5db  Build Version: 1.5.7152.31018
     For more information, please see http://wiki.ros.org/sw_urdf_exporter -->
<robot
  name="6dof2">

  <link name="world"/>

  <joint name="fixed" type="fixed">
    <origin rpy="1.5707963267948966192313216916398 0 0" xyz="2 0 1.5"/>
    <parent link="world"/>
    <child link="base"/>
  </joint>

  <link
    name="base">
    <inertial>
      <origin
        xyz="-2.73891844695728E-18 -0.0744815732910214 9.95019569027726E-18"
        rpy="0 0 0" />
      <mass
        value="2.51453966302872" />
      <inertia
        ixx="0.00664113392448905"
        ixy="-6.25766795110565E-19"
        ixz="-6.28386873662822E-19"
        iyy="0.00858257251487178"
        iyz="3.11349018192124E-20"
        izz="0.0105049216856327" />
    </inertial>
    <visual>
      <origin
        xyz="0 0 0"
        rpy="0 0 0" />
      <geometry>
        <mesh
          filename="meshes/base.STL" />
      </geometry>
      <material
        name="">
        <color
          rgba="0.752941176470588 0.752941176470588 0.752941176470588 1" />
      </material>
    </visual>
    <collision>
      <origin
        xyz="0 0 0"
        rpy="0 0 0" />
      <geometry>
        <mesh
          filename="meshes/base.obj" />
      </geometry>
    </collision>
  </link>
  <link
    name="link1">
    <inertial>
      <origin
        xyz="3.41096185655391E-17 -4.09916313817716E-17 0.124114609699705"
        rpy="0 0 0" />
      <mass
        value="2.74834554378783" />
      <inertia
        ixx="0.0123305472122744"
        ixy="-7.04731412115578E-19"
        ixz="1.29609506334721E-18"
        iyy="0.013050290242165"
        iyz="6.30912670329865E-19"
        izz="0.00622287447275937" />
    </inertial>
    <visual>
      <origin
        xyz="0 0 0"
        rpy="0 0 0" />
      <geometry>
        <mesh
          filename="meshes/link1.STL" />
      </geometry>
      <material
        name="">
        <color
          rgba="0.752941176470588 0.752941176470588 0.752941176470588 1" />
      </material>
    </visual>
    <collision>
      <origin
        xyz="0 0 0"
        rpy="0 0 0" />
      <geometry>
        <mesh
          filename="meshes/link1.obj" />
      </geometry>
    </collision>
  </link>
  <joint
    name="joint1"
    type="revolute">
    <origin
      xyz="0 -0.134 0"
      rpy="1.5707963267948966192313216916398 0 0" />
    <parent
      link="base" />
    <child
      link="link1" />
    <axis
      xyz="0 0 1" />
    <limit effort="300" lower="-2.96705972839" upper="2.96705972839" velocity="10"/>
    <safety_controller k_position="100" k_velocity="2" soft_lower_limit="-2.93215314335" soft_upper_limit="2.93215314335"/>
    <dynamics damping="0.5"/>
  </joint>
  <link
    name="link2">
    <inertial>
      <origin
        xyz="-0.000218810751891124 0.026890662918197 0.292281380257949"
        rpy="0 0 0" />
      <mass
        value="4.39917704175623" />
      <inertia
        ixx="0.0997480290462333"
        ixy="7.51902349299071E-07"
        ixz="3.47333063759316E-05"
        iyy="0.0984237035046946"
        iyz="0.00585777325239476"
        izz="0.0110945770203357" />
    </inertial>
    <visual>
      <origin
        xyz="0 0 0"
        rpy="0 0 0" />
      <geometry>
        <mesh
          filename="meshes/link2.STL" />
      </geometry>
      <material
        name="">
        <color
          rgba="0.752941176470588 0.752941176470588 0.752941176470588 1" />
      </material>
    </visual>
    <collision>
      <origin
        xyz="0 0 0"
        rpy="0 0 0" />
      <geometry>
        <mesh
          filename="meshes/link2.obj" />
      </geometry>
    </collision>
  </link>
  <joint
    name="joint2"
    type="revolute">
    <origin
      xyz="0 0 0.149"
      rpy="1.5707963267948966192313216916398 0 0" />
    <parent
      link="link1" />
    <child
      link="link2" />
    <axis
      xyz="1 0 0" />
    <limit effort="300" lower="-2.96705972839" upper="2.96705972839" velocity="10"/>
    <safety_controller k_position="100" k_velocity="2" soft_lower_limit="-2.93215314335" soft_upper_limit="2.93215314335"/>
    <dynamics damping="0.5"/>
  </joint>
  <link
    name="link3">
    <inertial>
      <origin
        xyz="-0.00559476888207244 0.0213407630819409 0.14502097364947"
        rpy="0 0 0" />
      <mass
        value="2.59789119906713" />
      <inertia
        ixx="0.0139828732176778"
        ixy="-1.49682793301122E-05"
        ixz="0.000182851790903711"
        iyy="0.0134396925169437"
        iyz="0.00131826879218898"
        izz="0.0068522237447728" />
    </inertial>
    <visual>
      <origin
        xyz="0 0 0"
        rpy="0 0 0" />
      <geometry>
        <mesh
          filename="meshes/link3.STL" />
      </geometry>
      <material
        name="">
        <color
          rgba="0.752941176470588 0.752941176470588 0.752941176470588 1" />
      </material>
    </visual>
    <collision>
      <origin
        xyz="0 0 0"
        rpy="0 0 0" />
      <geometry>
        <mesh
          filename="meshes/link3.obj" />
      </geometry>
    </collision>
  </link>
  <joint
    name="joint3"
    type="revolute">
    <origin
      xyz="0 0 0.45"
      rpy="0 0 0" />
    <parent
      link="link2" />
    <child
      link="link3" />
    <axis
      xyz="1 0 0" />
    <limit effort="300" lower="-2.96705972839" upper="2.96705972839" velocity="10"/>
    <safety_controller k_position="100" k_velocity="2" soft_lower_limit="-2.93215314335" soft_upper_limit="2.93215314335"/>
    <dynamics damping="0.5"/>
  </joint>
  <link
    name="link4">
    <inertial>
      <origin
        xyz="-8.32667268468867E-17 -1.38777878078145E-16 0.178682476846213"
        rpy="0 0 0" />
      <mass
        value="0.984623488432697" />
      <inertia
        ixx="0.00433140232016714"
        ixy="-4.54009659728305E-19"
        ixz="2.04981973235541E-18"
        iyy="0.00432310578227849"
        iyz="2.954450920023E-18"
        izz="0.00119086022251453" />
    </inertial>
    <visual>
      <origin
        xyz="0 0 0"
        rpy="0 0 0" />
      <geometry>
        <mesh
          filename="meshes/link4.STL" />
      </geometry>
      <material
        name="">
        <color
          rgba="0.752941176470588 0.752941176470588 0.752941176470588 1" />
      </material>
    </visual>
    <collision>
      <origin
        xyz="0 0 0"
        rpy="0 0 0" />
      <geometry>
        <mesh
          filename="meshes/link4.obj" />
      </geometry>
    </collision>
  </link>
  <joint
    name="joint4"
    type="revolute">
    <origin
      xyz="-0.00765 -0.004506 0.24781"
      rpy="0 0 0" />
    <parent
      link="link3" />
    <child
      link="link4" />
    <axis
      xyz="0 0 1" />
    <limit effort="300" lower="-2.96705972839" upper="2.96705972839" velocity="10"/>
    <safety_controller k_position="100" k_velocity="2" soft_lower_limit="-2.93215314335" soft_upper_limit="2.93215314335"/>
    <dynamics damping="0.5"/>
  </joint>
  <link
    name="link5">
    <inertial>
      <origin
        xyz="0.00029915 3.1919E-16 0.14335"
        rpy="0 0 0" />
      <mass
        value="1.0158" />
      <inertia
        ixx="0.0026469"
        ixy="-9.3089E-19"
        ixz="-3.8779E-05"
        iyy="0.0032546"
        iyz="-4.2826E-18"
        izz="0.0017589" />
    </inertial>
    <visual>
      <origin
        xyz="0 0 0"
        rpy="0 0 0" />
      <geometry>
        <mesh
          filename="meshes/link5.STL" />
      </geometry>
      <material
        name="">
        <color
          rgba="0.75294 0.75294 0.75294 1" />
      </material>
    </visual>
    <collision>
      <origin
        xyz="0 0 0"
        rpy="0 0 0" />
      <geometry>
        <mesh
          filename="meshes/link5.obj" />
      </geometry>
    </collision>
  </link>
  <joint
    name="joint5"
    type="revolute">
    <origin
      xyz="0 0 0.202183234570294"
      rpy="0.0181043837954633 0 0" />
    <parent
      link="link4" />
    <child
      link="link5" />
    <axis
      xyz="1 0 0" />
    <limit effort="300" lower="-2.96705972839" upper="2.96705972839" velocity="10"/>
    <safety_controller k_position="100" k_velocity="2" soft_lower_limit="-2.93215314335" soft_upper_limit="2.93215314335"/>
    <dynamics damping="0.5"/>
  </joint>
  
</robot>